<?xml version="1.0"?>
<robot xmlns:xacro="http://www.ros.org/wiki/xacro"  >

    <xacro:include filename="inertial_macros.xacro"/>

    <material name="white">
        <color rgba = "1 1 1 1" />
    </material>

    <material name="orange">
        <color rgba = "1 0.3 0.1 1" />
    </material>

    <material name="blue">
        <color rgba = "0.2 0.2 1 1" />
    </material>

    <material name="black">
        <color rgba = "0 0 0 1" />
    </material>

    <material name="red">
        <color rgba = "1 0 0 1" />
    </material>

    <link name="base_link">

    </link>

    <!-- BASE_FOOTPRINT LINK -->

    <joint name="base_footprint_joint" type="fixed">
        <parent link="base_link"/>
        <child link="base_footprint"/>
        <origin xyz="0 0 0" rpy="0 0 0"/>
    </joint>

    <link name="base_footprint">
    </link>

    <joint name="chassis_joint" type="fixed">
        <parent link="base_link"/>
        <child link="chassis"/>
        <origin xyz="0 0 0"/> <!--investigar para roboracecar-->
    </joint>

    <link name="chassis">
        <visual>
            <origin xyz="0.12 0 0.05"/>
            <geometry>
                <box size="0.24 0.16 0.10"/>
            </geometry>
            <material name="white"/>
        </visual>
        <collision>
            <origin xyz="0.12 0 0.05"/>
            <geometry>
                <box size="0.24 0.16 0.10"/>
            </geometry>
        </collision>
        <xacro:inertial_box mass="0.5" x="0.24" y="0.16" z="0.10">
            <origin xyz="0.12 0 0.05" rpy="0 0 0"/>
        </xacro:inertial_box>
    </link>

    <gazebo reference="chassis">
        <material>Gazebo/White</material>
    </gazebo>

    <!--RUEDAS TRASERAS-->

    <joint name="left_wheel_joint" type="continuous">
        <parent link="base_link"/>
        <child link="left_wheel"/>
        <origin xyz="0 0.10 0" rpy="-${pi/2} 0 0"/>
        <axis xyz="0 0 1"/>
    </joint>

    <link name="left_wheel">
        <visual>
            <geometry>
                <cylinder radius="0.04" length="0.04"/>
            </geometry>
            <material name="blue"/>
        </visual>
        <collision>
            <geometry>
                <sphere radius="0.04"/>
            </geometry>
        </collision>
        <xacro:inertial_cylinder mass="0.1" length="0.04" radius="0.04">
            <origin xyz="0 0 0" rpy="0 0 0"/>
        </xacro:inertial_cylinder>
    </link>

    <gazebo reference="left_wheel">
        <material>Gazebo/Blue</material>
    </gazebo>

    <joint name="right_wheel_joint" type="continuous">
        <parent link="base_link"/>
        <child link="right_wheel"/>
        <origin xyz="0 -0.10 0" rpy="-${pi/2} 0 0"/>
        <axis xyz="0 0 1"/>
    </joint>

    <link name="right_wheel">
        <visual>
            <geometry>
                <cylinder radius="0.04" length="0.04"/>
            </geometry>
            <material name="blue"/>
        </visual>
        <collision>
            <geometry>
                <sphere radius="0.04"/>
            </geometry>
        </collision>
        <xacro:inertial_cylinder mass="0.1" length="0.04" radius="0.04">
            <origin xyz="0 0 0" rpy="0 0 0"/>
        </xacro:inertial_cylinder>
    </link>

    <gazebo reference="right_wheel">
        <material>Gazebo/Blue</material>
    </gazebo>

    <!-- CASTER WHEEL LINK -->

    <joint name="caster_wheel_joint" type="fixed">
        <parent link="chassis"/>
        <child link="caster_wheel"/>
        <origin xyz="0.24 0 0"/>
    </joint>


    <link name="caster_wheel">
        <visual>
            <geometry>
                <sphere radius="0.04"/>
            </geometry>
            <material name="black"/>
        </visual>
        <collision>
            <geometry>
                <sphere radius="0.04"/>
            </geometry>
        </collision>
        <xacro:inertial_sphere mass="0.1" radius="0.04">
            <origin xyz="0.18 0 0" rpy="0 0 0"/>
        </xacro:inertial_sphere>
    </link>

    <gazebo reference="caster_wheel">
        <material>Gazebo/Black</material>
        <mu1 value="0.001"/>
        <mu2 value="0.001"/>
    </gazebo>

     <!--RUEDAS DELANTERAS

    <joint name="front_left_steer_joint" type="revolute">
        <parent link="base_link"/>
        <child link="front_left_steer_link"/>
        <origin xyz="0.24 0.10 0" rpy="0 0 0"/>
        <axis xyz="0 0 1"/>
        <limit lower="-0.5" upper="0.5" effort="5" velocity="1"/>
    </joint>
    
    <link name="front_left_steer_link">
        <visual>
            <origin xyz="0 0 0" rpy="0 0 0"/>
            <geometry>
                <box size="0.01 0.01 0.01"/>
            </geometry>
            <material name="black"/>
        </visual>
    </link>

    <joint name="front_left_wheel_joint" type="continuous">
        <parent link="front_left_steer_link"/>
        <child link="front_left_wheel"/>
        <origin xyz="0 0 0" rpy="-${pi/2} 0 0"/>
        <axis xyz="0 0 1"/>
    </joint>
           
    <link name="front_left_wheel">
        <visual>
            <geometry>
                <cylinder radius="0.04" length="0.04"/>
            </geometry>
            <material name="blue"/>
        </visual>
        <collision>
            <geometry>
                <cylinder radius="0.04" length="0.04"/>
            </geometry>
        </collision>
        <xacro:inertial_cylinder mass="0.1" length="0.04" radius="0.04">
            <origin xyz="0 0 0" rpy="0 0 0"/>
        </xacro:inertial_cylinder>
    </link>

    <gazebo reference="front_left_wheel">
        <material>Gazebo/Black</material>
    </gazebo>

    <joint name="front_right_steer_joint" type="revolute">
        <parent link="base_link"/>
        <child link="front_right_steer_link"/>
        <origin xyz="0.24 -0.10 0" rpy="0 0 0"/>
        <axis xyz="0 0 -1"/>
        <limit lower="-0.5" upper="0.5" effort="5" velocity="1"/>
    </joint>
    
    <link name="front_right_steer_link">
        <visual>
            <origin xyz="0 0 0" rpy="0 0 0"/>
            <geometry>
                <box size="0.01 0.01 0.01"/>
            </geometry>
            <material name="black"/>
        </visual>
    </link>

    <joint name="front_right_wheel_joint" type="continuous">
        <parent link="front_right_steer_link"/>
        <child link="front_right_wheel"/>
        <origin xyz="0 0 0" rpy="${pi/2} 0 0"/>
        <axis xyz="0 0 1"/>
    </joint>
           
    <link name="front_right_wheel">
        <visual>
            <geometry>
                <cylinder radius="0.04" length="0.04"/>
            </geometry>
            <material name="blue"/>
        </visual>
        <collision>
            <geometry>
                <cylinder radius="0.04" length="0.04"/>
            </geometry>
        </collision>
        <xacro:inertial_cylinder mass="0.1" length="0.04" radius="0.04">
            <origin xyz="0 0 0" rpy="0 0 0"/>
        </xacro:inertial_cylinder>
    </link>

    <gazebo reference="front_right_wheel">
        <material>Gazebo/Black</material>
    </gazebo>-->

    <!--LIDAR-->
    <joint name="laser_joint" type="fixed">
        <parent link="chassis"/>
        <child link="laser_frame"/>
        <origin xyz="0.2 0 0.12" rpy="0 0 0"/>
    </joint>

    <link name="laser_frame">
        <visual>
            <geometry>
                <cylinder radius="0.033" length="0.04"/>
            </geometry>
            <material name="red"/>
        </visual>
        <collision>
            <geometry>
                <cylinder radius="0.033" length="0.04"/>
            </geometry>
        </collision>
        <xacro:inertial_cylinder mass="0.19" length="0.04" radius="0.033">
            <origin xyz="0 0 0" rpy="0 0 0"/>
        </xacro:inertial_cylinder>
    </link>

    <gazebo reference="laser_frame">
        <material>Gazebo/Red</material>

        <sensor name="laser" type="ray">
            <pose> 0 0 0 0 0 0 </pose>
            <visualize>true</visualize>
            <update_rate>10</update_rate>
            <ray>
                <scan>
                    <horizontal>
                        <samples>360</samples>
                        <min_angle>-3.14</min_angle>
                        <max_angle>3.14</max_angle>
                    </horizontal>
                </scan>
                <range>
                    <min>0.3</min>
                    <max>12</max>
                </range>
            </ray>
            <plugin name="laser_controller" filename="libgazebo_ros_ray_sensor.so">
                <ros>
                    <argument>~/out:=scan</argument>
                </ros>
                <output_type>sensor_msgs/LaserScan</output_type>
                <frame_name>laser_frame</frame_name>
            </plugin>
        </sensor>
    </gazebo>

</robot>
